Workbook

Sheet transactions_jan2024
A1: transaction_id | B1: user_id | C1: transaction_date | D1: transaction_type | E1: amount_ngn | F1: status | G1: channel | H1: region | I1: FLAG_duplicate_id | J1: FLAG_negative_amt | K1: FLAG_bad_date | L1: FLAG_bad_status | M1: FLAG_missing_region | N1: ISSUE_SUMMARY
A2: TXN-0001 | B2: USR-3615 | C2: 45302 | D2: Transfer | E2: 29900 | F2: Failed | G2: Web | H2: Lagos | I2: =IF(COUNTIF($A$2:$A$51,A2)>1,"DUPLICATE","OK") -> OK | J2: =IF(E2<0,"NEGATIVE","OK") -> OK | K2: =IF(YEAR(C2)<>2024,"BAD YEAR: "&YEAR(C2),"OK") -> OK | L2: =IF(AND(F2<>"Success",F2<>"Failed",F2<>"Pending"),"BAD CASING: '"&F2&"'","OK") -> OK | M2: =IF(H2="","MISSING","OK") -> OK | N2: =IF(I2="DUPLICATE","Duplicate ID: "&A2,IF(J2="NEGATIVE","Negative amount: ₦"&TEXT(E2,"#,##0"),IF(K2<>"OK","Date outlier: "&TEXT(C2,"DD-MMM-YYYY"),IF(L2<>"OK","Status casing: '"&F2&"' should be title case",IF(M2="MISSING","Region: NULL/missing","No issues found"))))) -> No issues found
A3: TXN-0002 | B3: USR-1106 | C3: 45306 | D3: Deposit | E3: 91310 | F3: Success | G3: Web | H3: Ibadan | I3: =IF(COUNTIF($A$2:$A$51,A3)>1,"DUPLICATE","OK") -> OK | J3: =IF(E3<0,"NEGATIVE","OK") -> OK | K3: =IF(YEAR(C3)<>2024,"BAD YEAR: "&YEAR(C3),"OK") -> OK | L3: =IF(AND(F3<>"Success",F3<>"Failed",F3<>"Pending"),"BAD CASING: '"&F3&"'","OK") -> OK | M3: =IF(H3="","MISSING","OK") -> OK | N3: =IF(I3="DUPLICATE","Duplicate ID: "&A3,IF(J3="NEGATIVE","Negative amount: ₦"&TEXT(E3,"#,##0"),IF(K3<>"OK","Date outlier: "&TEXT(C3,"DD-MMM-YYYY"),IF(L3<>"OK","Status casing: '"&F3&"' should be title case",IF(M3="MISSING","Region: NULL/missing","No issues found"))))) -> No issues found
A4: TXN-0003 | B4: USR-2679 | C4: 45314 | D4: Transfer | E4: 48340 | F4: Pending | G4: USSD | H4: Lagos | I4: =IF(COUNTIF($A$2:$A$51,A4)>1,"DUPLICATE","OK") -> DUPLICATE | J4: =IF(E4<0,"NEGATIVE","OK") -> OK | K4: =IF(YEAR(C4)<>2024,"BAD YEAR: "&YEAR(C4),"OK") -> OK | L4: =IF(AND(F4<>"Success",F4<>"Failed",F4<>"Pending"),"BAD CASING: '"&F4&"'","OK") -> OK | M4: =IF(H4="","MISSING","OK") -> OK | N4: =IF(I4="DUPLICATE","Duplicate ID: "&A4,IF(J4="NEGATIVE","Negative amount: ₦"&TEXT(E4,"#,##0"),IF(K4<>"OK","Date outlier: "&TEXT(C4,"DD-MMM-YYYY"),IF(L4<>"OK","Status casing: '"&F4&"' should be title case",IF(M4="MISSING","Region: NULL/missing","No issues found"))))) -> Duplicate ID: TXN-0003
A5: TXN-0004 | B5: USR-2535 | C5: 45300 | D5: Withdrawal | E5: 15660 | F5: Success | G5: Web | H5: Lagos | I5: =IF(COUNTIF($A$2:$A$51,A5)>1,"DUPLICATE","OK") -> OK | J5: =IF(E5<0,"NEGATIVE","OK") -> OK | K5: =IF(YEAR(C5)<>2024,"BAD YEAR: "&YEAR(C5),"OK") -> OK | L5: =IF(AND(F5<>"Success",F5<>"Failed",F5<>"Pending"),"BAD CASING: '"&F5&"'","OK") -> OK | M5: =IF(H5="","MISSING","OK") -> OK | N5: =IF(I5="DUPLICATE","Duplicate ID: "&A5,IF(J5="NEGATIVE","Negative amount: ₦"&TEXT(E5,"#,##0"),IF(K5<>"OK","Date outlier: "&TEXT(C5,"DD-MMM-YYYY"),IF(L5<>"OK","Status casing: '"&F5&"' should be title case",IF(M5="MISSING","Region: NULL/missing","No issues found"))))) -> No issues found
A6: TXN-0005 | B6: USR-7873 | C6: 45312 | D6: Airtime | E6: 21040 | F6: Success | G6: USSD | I6: =IF(COUNTIF($A$2:$A$51,A6)>1,"DUPLICATE","OK") -> OK | J6: =IF(E6<0,"NEGATIVE","OK") -> OK | K6: =IF(YEAR(C6)<>2024,"BAD YEAR: "&YEAR(C6),"OK") -> OK | L6: =IF(AND(F6<>"Success",F6<>"Failed",F6<>"Pending"),"BAD CASING: '"&F6&"'","OK") -> OK | M6: =IF(H6="","MISSING","OK") -> MISSING | N6: =IF(I6="DUPLICATE","Duplicate ID: "&A6,IF(J6="NEGATIVE","Negative amount: ₦"&TEXT(E6,"#,##0"),IF(K6<>"OK","Date outlier: "&TEXT(C6,"DD-MMM-YYYY"),IF(L6<>"OK","Status casing: '"&F6&"' should be title case",IF(M6="MISSING","Region: NULL/missing","No issues found"))))) -> Region: NULL/missing
A7: TXN-0006 | B7: USR-6574 | C7: 45316 | D7: Transfer | E7: 7100 | F7: success | G7: App | H7: Abuja | I7: =IF(COUNTIF($A$2:$A$51,A7)>1,"DUPLICATE","OK") -> OK | J7: =IF(E7<0,"NEGATIVE","OK") -> OK | K7: =IF(YEAR(C7)<>2024,"BAD YEAR: "&YEAR(C7),"OK") -> OK | L7: =IF(AND(F7<>"Success",F7<>"Failed",F7<>"Pending"),"BAD CASING: '"&F7&"'","OK") -> OK | M7: =IF(H7="","MISSING","OK") -> OK | N7: =IF(I7="DUPLICATE","Duplicate ID: "&A7,IF(J7="NEGATIVE","Negative amount: ₦"&TEXT(E7,"#,##0"),IF(K7<>"OK","Date outlier: "&TEXT(C7,"DD-MMM-YYYY"),IF(L7<>"OK","Status casing: '"&F7&"' should be title case",IF(M7="MISSING","Region: NULL/missing","No issues found"))))) -> No issues found
A8: TXN-0007 | B8: USR-4527 | C8: 45322 | D8: Deposit | E8: 18930 | F8: Success | G8: Agent | H8: Abuja | I8: =IF(COUNTIF($A$2:$A$51,A8)>1,"DUPLICATE","OK") -> OK | J8: =IF(E8<0,"NEGATIVE","OK") -> OK | K8: =IF(YEAR(C8)<>2024,"BAD YEAR: "&YEAR(C8),"OK") -> OK | L8: =IF(AND(F8<>"Success",F8<>"Failed",F8<>"Pending"),"BAD CASING: '"&F8&"'","OK") -> OK | M8: =IF(H8="","MISSING","OK") -> OK | N8: =IF(I8="DUPLICATE","Duplicate ID: "&A8,IF(J8="NEGATIVE","Negative amount: ₦"&TEXT(E8,"#,##0"),IF(K8<>"OK","Date outlier: "&TEXT(C8,"DD-MMM-YYYY"),IF(L8<>"OK","Status casing: '"&F8&"' should be title case",IF(M8="MISSING","Region: NULL/missing","No issues found"))))) -> No issues found
A9: TXN-0003 | B9: USR-2424 | C9: 45296 | D9: Airtime | E9: 441650 | F9: Success | G9: Agent | H9: Kano | I9: =IF(COUNTIF($A$2:$A$51,A9)>1,"DUPLICATE","OK") -> DUPLICATE | J9: =IF(E9<0,"NEGATIVE","OK") -> OK | K9: =IF(YEAR(C9)<>2024,"BAD YEAR: "&YEAR(C9),"OK") -> OK | L9: =IF(AND(F9<>"Success",F9<>"Failed",F9<>"Pending"),"BAD CASING: '"&F9&"'","OK") -> OK | M9: =IF(H9="","MISSING","OK") -> OK | N9: =IF(I9="DUPLICATE","Duplicate ID: "&A9,IF(J9="NEGATIVE","Negative amount: ₦"&TEXT(E9,"#,##0"),IF(K9<>"OK","Date outlier: "&TEXT(C9,"DD-MMM-YYYY"),IF(L9<>"OK","Status casing: '"&F9&"' should be title case",IF(M9="MISSING","Region: NULL/missing","No issues found"))))) -> Duplicate ID: TXN-0003
A10: TXN-0009 | B10: USR-9935 | C10: 45296 | D10: Deposit | E10: 4540 | F10: Failed | G10: USSD | H10: Abuja | I10: =IF(COUNTIF($A$2:$A$51,A10)>1,"DUPLICATE","OK") -> OK | J10: =IF(E10<0,"NEGATIVE","OK") -> OK | K10: =IF(YEAR(C10)<>2024,"BAD YEAR: "&YEAR(C10),"OK") -> OK | L10: =IF(AND(F10<>"Success",F10<>"Failed",F10<>"Pending"),"BAD CASING: '"&F10&"'","OK") -> OK | M10: =IF(H10="","MISSING","OK") -> OK | N10: =IF(I10="DUPLICATE","Duplicate ID: "&A10,IF(J10="NEGATIVE","Negative amount: ₦"&TEXT(E10,"#,##0"),IF(K10<>"OK","Date outlier: "&TEXT(C10,"DD-MMM-YYYY"),IF(L10<>"OK","Status casing: '"&F10&"' should be title case",IF(M10="MISSING","Region: NULL/missing","No issues found"))))) -> No issues found
A11: TXN-0010 | B11: USR-7924 | C11: 45313 | D11: Withdrawal | E11: -250080 | F11: Pending | G11: Web | H11: Ibadan | I11: =IF(COUNTIF($A$2:$A$51,A11)>1,"DUPLICATE","OK") -> OK | J11: =IF(E11<0,"NEGATIVE","OK") -> NEGATIVE | K11: =IF(YEAR(C11)<>2024,"BAD YEAR: "&YEAR(C11),"OK") -> OK | L11: =IF(AND(F11<>"Success",F11<>"Failed",F11<>"Pending"),"BAD CASING: '"&F11&"'","OK") -> OK | M11: =IF(H11="","MISSING","OK") -> OK | N11: =IF(I11="DUPLICATE","Duplicate ID: "&A11,IF(J11="NEGATIVE","Negative amount: "&TEXT(E11,"#,##0"),IF(K11<>"OK","Date outlier: "&TEXT(C11,"DD-MMM-YYYY"),IF(L11<>"OK","Status casing: '"&F11&"' should be title case",IF(M11="MISSING","Region: NULL/missing","No issues found"))))) -> Negative amount: -250,080
A12: TXN-0011 | B12: USR-5552 | C12: 45322 | D12: Transfer | E12: 49680 | F12: Failed | G12: Web | H12: Lagos | I12: =IF(COUNTIF($A$2:$A$51,A12)>1,"DUPLICATE","OK") -> OK | J12: =IF(E12<0,"NEGATIVE","OK") -> OK | K12: =IF(YEAR(C12)<>2024,"BAD YEAR: "&YEAR(C12),"OK") -> OK | L12: =IF(AND(F12<>"Success",F12<>"Failed",F12<>"Pending"),"BAD CASING: '"&F12&"'","OK") -> OK | M12: =IF(H12="","MISSING","OK") -> OK | N12: =IF(I12="DUPLICATE","Duplicate ID: "&A12,IF(J12="NEGATIVE","Negative amount: ₦"&TEXT(E12,"#,##0"),IF(K12<>"OK","Date outlier: "&TEXT(C12,"DD-MMM-YYYY"),IF(L12<>"OK","Status casing: '"&F12&"' should be title case",IF(M12="MISSING","Region: NULL/missing","No issues found"))))) -> No issues found
A13: TXN-0012 | B13: USR-7912 | C13: 45305 | D13: Airtime | E13: 428580 | F13: Success | G13: USSD | I13: =IF(COUNTIF($A$2:$A$51,A13)>1,"DUPLICATE","OK") -> OK | J13: =IF(E13<0,"NEGATIVE","OK") -> OK | K13: =IF(YEAR(C13)<>2024,"BAD YEAR: "&YEAR(C13),"OK") -> OK | L13: =IF(AND(F13<>"Success",F13<>"Failed",F13<>"Pending"),"BAD CASING: '"&F13&"'","OK") -> OK | M13: =IF(H13="","MISSING","OK") -> MISSING | N13: =IF(I13="DUPLICATE","Duplicate ID: "&A13,IF(J13="NEGATIVE","Negative amount: ₦"&TEXT(E13,"#,##0"),IF(K13<>"OK","Date outlier: "&TEXT(C13,"DD-MMM-YYYY"),IF(L13<>"OK","Status casing: '"&F13&"' should be title case",IF(M13="MISSING","Region: NULL/missing","No issues found"))))) -> Region: NULL/missing
A14: TXN-0013 | B14: USR-4527 | C14: 45295 | D14: Bill Payment | E14: 4660 | F14: SUCCESS | G14: USSD | H14: Ibadan | I14: =IF(COUNTIF($A$2:$A$51,A14)>1,"DUPLICATE","OK") -> OK | J14: =IF(E14<0,"NEGATIVE","OK") -> OK | K14: =IF(YEAR(C14)<>2024,"BAD YEAR: "&YEAR(C14),"OK") -> OK | L14: =IF(AND(F14<>"Success",F14<>"Failed",F14<>"Pending"),"BAD CASING: '"&F14&"'","OK") -> OK | M14: =IF(H14="","MISSING","OK") -> OK | N14: =IF(I14="DUPLICATE","Duplicate ID: "&A14,IF(J14="NEGATIVE","Negative amount: ₦"&TEXT(E14,"#,##0"),IF(K14<>"OK","Date outlier: "&TEXT(C14,"DD-MMM-YYYY"),IF(L14<>"OK","Status casing: '"&F14&"' should be title case",IF(M14="MISSING","Region: NULL/missing","No issues found"))))) -> No issues found
A15: TXN-0014 | B15: USR-3615 | C15: 45321 | D15: Deposit | E15: 44250 | F15: Success | G15: Web | H15: Kano | I15: =IF(COUNTIF($A$2:$A$51,A15)>1,"DUPLICATE","OK") -> OK | J15: =IF(E15<0,"NEGATIVE","OK") -> OK | K15: =IF(YEAR(C15)<>2024,"BAD YEAR: "&YEAR(C15),"OK") -> OK | L15: =IF(AND(F15<>"Success",F15<>"Failed",F15<>"Pending"),"BAD CASING: '"&F15&"'","OK") -> OK | M15: =IF(H15="","MISSING","OK") -> OK | N15: =IF(I15="DUPLICATE","Duplicate ID: "&A15,IF(J15="NEGATIVE","Negative amount: ₦"&TEXT(E15,"#,##0"),IF(K15<>"OK","Date outlier: "&TEXT(C15,"DD-MMM-YYYY"),IF(L15<>"OK","Status casing: '"&F15&"' should be title case",IF(M15="MISSING","Region: NULL/missing","No issues found"))))) -> No issues found
A16: TXN-0015 | B16: USR-9935 | C16: 45293 | D16: Airtime | E16: 10610 | F16: Failed | G16: USSD | H16: Abuja | I16: =IF(COUNTIF($A$2:$A$51,A16)>1,"DUPLICATE","OK") -> DUPLICATE | J16: =IF(E16<0,"NEGATIVE","OK") -> OK | K16: =IF(YEAR(C16)<>2024,"BAD YEAR: "&YEAR(C16),"OK") -> OK | L16: =IF(AND(F16<>"Success",F16<>"Failed",F16<>"Pending"),"BAD CASING: '"&F16&"'","OK") -> OK | M16: =IF(H16="","MISSING","OK") -> OK | N16: =IF(I16="DUPLICATE","Duplicate ID: "&A16,IF(J16="NEGATIVE","Negative amount: ₦"&TEXT(E16,"#,##0"),IF(K16<>"OK","Date outlier: "&TEXT(C16,"DD-MMM-YYYY"),IF(L16<>"OK","Status casing: '"&F16&"' should be title case",IF(M16="MISSING","Region: NULL/missing","No issues found"))))) -> Duplicate ID: TXN-0015
A17: TXN-0016 | B17: USR-8359 | C17: 45307 | D17: Deposit | E17: 326650 | F17: Success | G17: USSD | H17: Ibadan | I17: =IF(COUNTIF($A$2:$A$51,A17)>1,"DUPLICATE","OK") -> OK | J17: =IF(E17<0,"NEGATIVE","OK") -> OK | K17: =IF(YEAR(C17)<>2024,"BAD YEAR: "&YEAR(C17),"OK") -> OK | L17: =IF(AND(F17<>"Success",F17<>"Failed",F17<>"Pending"),"BAD CASING: '"&F17&"'","OK") -> OK | M17: =IF(H17="","MISSING","OK") -> OK | N17: =IF(I17="DUPLICATE","Duplicate ID: "&A17,IF(J17="NEGATIVE","Negative amount: ₦"&TEXT(E17,"#,##0"),IF(K17<>"OK","Date outlier: "&TEXT(C17,"DD-MMM-YYYY"),IF(L17<>"OK","Status casing: '"&F17&"' should be title case",IF(M17="MISSING","Region: NULL/missing","No issues found"))))) -> No issues found
A18: TXN-0017 | B18: USR-3615 | C18: 38003 | D18: Airtime | E18: 402160 | F18: Success | G18: Agent | H18: Lagos | I18: =IF(COUNTIF($A$2:$A$51,A18)>1,"DUPLICATE","OK") -> OK | J18: =IF(E18<0,"NEGATIVE","OK") -> OK | K18: =IF(YEAR(C18)<>2024,"BAD YEAR: "&YEAR(C18),"OK") -> BAD YEAR: 2004 | L18: =IF(AND(F18<>"Success",F18<>"Failed",F18<>"Pending"),"BAD CASING: '"&F18&"'","OK") -> OK | M18: =IF(H18="","MISSING","OK") -> OK | N18: =IF(I18="DUPLICATE","Duplicate ID: "&A18,IF(J18="NEGATIVE","Negative amount: ₦"&TEXT(E18,"#,##0"),IF(K18<>"OK","Date outlier: "&TEXT(C18,"DD-MMM-YYYY"),IF(L18<>"OK","Status casing: '"&F18&"' should be title case",IF(M18="MISSING","Region: NULL/missing","No issues found"))))) -> Date outlier: 17-Jan-2004
A19: TXN-0018 | B19: USR-9935 | C19: 45299 | D19: Transfer | E19: 358440 | F19: Success | G19: USSD | H19: Lagos | I19: =IF(COUNTIF($A$2:$A$51,A19)>1,"DUPLICATE","OK") -> OK | J19: =IF(E19<0,"NEGATIVE","OK") -> OK | K19: =IF(YEAR(C19)<>2024,"BAD YEAR: "&YEAR(C19),"OK") -> OK | L19: =IF(AND(F19<>"Success",F19<>"Failed",F19<>"Pending"),"BAD CASING: '"&F19&"'","OK") -> OK | M19: =IF(H19="","MISSING","OK") -> OK | N19: =IF(I19="DUPLICATE","Duplicate ID: "&A19,IF(J19="NEGATIVE","Negative amount: ₦"&TEXT(E19,"#,##0"),IF(K19<>"OK","Date outlier: "&TEXT(C19,"DD-MMM-YYYY"),IF(L19<>"OK","Status casing: '"&F19&"' should be title case",IF(M19="MISSING","Region: NULL/missing","No issues found"))))) -> No issues found
A20: TXN-0019 | B20: USR-5506 | C20: 45314 | D20: Transfer | E20: 9420 | F20: Success | G20: USSD | H20: Kano | I20: =IF(COUNTIF($A$2:$A$51,A20)>1,"DUPLICATE","OK") -> OK | J20: =IF(E20<0,"NEGATIVE","OK") -> OK | K20: =IF(YEAR(C20)<>2024,"BAD YEAR: "&YEAR(C20),"OK") -> OK | L20: =IF(AND(F20<>"Success",F20<>"Failed",F20<>"Pending"),"BAD CASING: '"&F20&"'","OK") -> OK | M20: =IF(H20="","MISSING","OK") -> OK | N20: =IF(I20="DUPLICATE","Duplicate ID: "&A20,IF(J20="NEGATIVE","Negative amount: ₦"&TEXT(E20,"#,##0"),IF(K20<>"OK","Date outlier: "&TEXT(C20,"DD-MMM-YYYY"),IF(L20<>"OK","Status casing: '"&F20&"' should be title case",IF(M20="MISSING","Region: NULL/missing","No issues found"))))) -> No issues found
A21: TXN-0020 | B21: USR-8359 | C21: 45307 | D21: Airtime | E21: 429240 | F21: Success | G21: USSD | I21: =IF(COUNTIF($A$2:$A$51,A21)>1,"DUPLICATE","OK") -> OK | J21: =IF(E21<0,"NEGATIVE","OK") -> OK | K21: =IF(YEAR(C21)<>2024,"BAD YEAR: "&YEAR(C21),"OK") -> OK | L21: =IF(AND(F21<>"Success",F21<>"Failed",F21<>"Pending"),"BAD CASING: '"&F21&"'","OK") -> OK | M21: =IF(H21="","MISSING","OK") -> MISSING | N21: =IF(I21="DUPLICATE","Duplicate ID: "&A21,IF(J21="NEGATIVE","Negative amount: ₦"&TEXT(E21,"#,##0"),IF(K21<>"OK","Date outlier: "&TEXT(C21,"DD-MMM-YYYY"),IF(L21<>"OK","Status casing: '"&F21&"' should be title case",IF(M21="MISSING","Region: NULL/missing","No issues found"))))) -> Region: NULL/missing
A22: TXN-0021 | B22: USR-7924 | C22: 45305 | D22: Airtime | E22: 11350 | F22: Success | G22: Agent | H22: Port Harcourt | I22: =IF(COUNTIF($A$2:$A$51,A22)>1,"DUPLICATE","OK") -> OK | J22: =IF(E22<0,"NEGATIVE","OK") -> OK | K22: =IF(YEAR(C22)<>2024,"BAD YEAR: "&YEAR(C22),"OK") -> OK | L22: =IF(AND(F22<>"Success",F22<>"Failed",F22<>"Pending"),"BAD CASING: '"&F22&"'","OK") -> OK | M22: =IF(H22="","MISSING","OK") -> OK | N22: =IF(I22="DUPLICATE","Duplicate ID: "&A22,IF(J22="NEGATIVE","Negative amount: ₦"&TEXT(E22,"#,##0"),IF(K22<>"OK","Date outlier: "&TEXT(C22,"DD-MMM-YYYY"),IF(L22<>"OK","Status casing: '"&F22&"' should be title case",IF(M22="MISSING","Region: NULL/missing","No issues found"))))) -> No issues found
A23: TXN-0015 | B23: USR-5552 | C23: 45315 | D23: Transfer | E23: 261090 | F23: Success | G23: App | H23: Abuja | I23: =IF(COUNTIF($A$2:$A$51,A23)>1,"DUPLICATE","OK") -> DUPLICATE | J23: =IF(E23<0,"NEGATIVE","OK") -> OK | K23: =IF(YEAR(C23)<>2024,"BAD YEAR: "&YEAR(C23),"OK") -> OK | L23: =IF(AND(F23<>"Success",F23<>"Failed",F23<>"Pending"),"BAD CASING: '"&F23&"'","OK") -> OK | M23: =IF(H23="","MISSING","OK") -> OK | N23: =IF(I23="DUPLICATE","Duplicate ID: "&A23,IF(J23="NEGATIVE","Negative amount: ₦"&TEXT(E23,"#,##0"),IF(K23<>"OK","Date outlier: "&TEXT(C23,"DD-MMM-YYYY"),IF(L23<>"OK","Status casing: '"&F23&"' should be title case",IF(M23="MISSING","Region: NULL/missing","No issues found"))))) -> Duplicate ID: TXN-0015
A24: TXN-0023 | B24: USR-2679 | C24: 45298 | D24: Deposit | E24: 4180 | F24: Success | G24: USSD | H24: Lagos | I24: =IF(COUNTIF($A$2:$A$51,A24)>1,"DUPLICATE","OK") -> OK | J24: =IF(E24<0,"NEGATIVE","OK") -> OK | K24: =IF(YEAR(C24)<>2024,"BAD YEAR: "&YEAR(C24),"OK") -> OK | L24: =IF(AND(F24<>"Success",F24<>"Failed",F24<>"Pending"),"BAD CASING: '"&F24&"'","OK") -> OK | M24: =IF(H24="","MISSING","OK") -> OK | N24: =IF(I24="DUPLICATE","Duplicate ID: "&A24,IF(J24="NEGATIVE","Negative amount: ₦"&TEXT(E24,"#,##0"),IF(K24<>"OK","Date outlier: "&TEXT(C24,"DD-MMM-YYYY"),IF(L24<>"OK","Status casing: '"&F24&"' should be title case",IF(M24="MISSING","Region: NULL/missing","No issues found"))))) -> No issues found
A25: TXN-0024 | B25: USR-4811 | C25: 45317 | D25: Deposit | E25: 391910 | F25: Failed | G25: App | H25: Abuja | I25: =IF(COUNTIF($A$2:$A$51,A25)>1,"DUPLICATE","OK") -> OK | J25: =IF(E25<0,"NEGATIVE","OK") -> OK | K25: =IF(YEAR(C25)<>2024,"BAD YEAR: "&YEAR(C25),"OK") -> OK | L25: =IF(AND(F25<>"Success",F25<>"Failed",F25<>"Pending"),"BAD CASING: '"&F25&"'","OK") -> OK | M25: =IF(H25="","MISSING","OK") -> OK | N25: =IF(I25="DUPLICATE","Duplicate ID: "&A25,IF(J25="NEGATIVE","Negative amount: ₦"&TEXT(E25,"#,##0"),IF(K25<>"OK","Date outlier: "&TEXT(C25,"DD-MMM-YYYY"),IF(L25<>"OK","Status casing: '"&F25&"' should be title case",IF(M25="MISSING","Region: NULL/missing","No issues found"))))) -> No issues found
A26: TXN-0025 | B26: USR-3286 | C26: 45305 | D26: Withdrawal | E26: 4440 | F26: failed | G26: App | H26: Port Harcourt | I26: =IF(COUNTIF($A$2:$A$51,A26)>1,"DUPLICATE","OK") -> OK | J26: =IF(E26<0,"NEGATIVE","OK") -> OK | K26: =IF(YEAR(C26)<>2024,"BAD YEAR: "&YEAR(C26),"OK") -> OK | L26: =IF(AND(F26<>"Success",F26<>"Failed",F26<>"Pending"),"BAD CASING: '"&F26&"'","OK") -> OK | M26: =IF(H26="","MISSING","OK") -> OK | N26: =IF(I26="DUPLICATE","Duplicate ID: "&A26,IF(J26="NEGATIVE","Negative amount: ₦"&TEXT(E26,"#,##0"),IF(K26<>"OK","Date outlier: "&TEXT(C26,"DD-MMM-YYYY"),IF(L26<>"OK","Status casing: '"&F26&"' should be title case",IF(M26="MISSING","Region: NULL/missing","No issues found"))))) -> No issues found
A27: TXN-0026 | B27: USR-2424 | C27: 45321 | D27: Withdrawal | E27: 415210 | F27: Pending | G27: Agent | H27: Abuja | I27: =IF(COUNTIF($A$2:$A$51,A27)>1,"DUPLICATE","OK") -> OK | J27: =IF(E27<0,"NEGATIVE","OK") -> OK | K27: =IF(YEAR(C27)<>2024,"BAD YEAR: "&YEAR(C27),"OK") -> OK | L27: =IF(AND(F27<>"Success",F27<>"Failed",F27<>"Pending"),"BAD CASING: '"&F27&"'","OK") -> OK | M27: =IF(H27="","MISSING","OK") -> OK | N27: =IF(I27="DUPLICATE","Duplicate ID: "&A27,IF(J27="NEGATIVE","Negative amount: ₦"&TEXT(E27,"#,##0"),IF(K27<>"OK","Date outlier: "&TEXT(C27,"DD-MMM-YYYY"),IF(L27<>"OK","Status casing: '"&F27&"' should be title case",IF(M27="MISSING","Region: NULL/missing","No issues found"))))) -> No issues found
A28: TXN-0027 | B28: USR-2679 | C28: 45301 | D28: Airtime | E28: 435740 | F28: Success | G28: Web | H28: Lagos | I28: =IF(COUNTIF($A$2:$A$51,A28)>1,"DUPLICATE","OK") -> OK | J28: =IF(E28<0,"NEGATIVE","OK") -> OK | K28: =IF(YEAR(C28)<>2024,"BAD YEAR: "&YEAR(C28),"OK") -> OK | L28: =IF(AND(F28<>"Success",F28<>"Failed",F28<>"Pending"),"BAD CASING: '"&F28&"'","OK") -> OK | M28: =IF(H28="","MISSING","OK") -> OK | N28: =IF(I28="DUPLICATE","Duplicate ID: "&A28,IF(J28="NEGATIVE","Negative amount: ₦"&TEXT(E28,"#,##0"),IF(K28<>"OK","Date outlier: "&TEXT(C28,"DD-MMM-YYYY"),IF(L28<>"OK","Status casing: '"&F28&"' should be title case",IF(M28="MISSING","Region: NULL/missing","No issues found"))))) -> No issues found
A29: TXN-0028 | B29: USR-1409 | C29: 45310 | D29: Withdrawal | E29: 4620 | F29: Pending | G29: App | H29: Abuja | I29: =IF(COUNTIF($A$2:$A$51,A29)>1,"DUPLICATE","OK") -> OK | J29: =IF(E29<0,"NEGATIVE","OK") -> OK | K29: =IF(YEAR(C29)<>2024,"BAD YEAR: "&YEAR(C29),"OK") -> OK | L29: =IF(AND(F29<>"Success",F29<>"Failed",F29<>"Pending"),"BAD CASING: '"&F29&"'","OK") -> OK | M29: =IF(H29="","MISSING","OK") -> OK | N29: =IF(I29="DUPLICATE","Duplicate ID: "&A29,IF(J29="NEGATIVE","Negative amount: ₦"&TEXT(E29,"#,##0"),IF(K29<>"OK","Date outlier: "&TEXT(C29,"DD-MMM-YYYY"),IF(L29<>"OK","Status casing: '"&F29&"' should be title case",IF(M29="MISSING","Region: NULL/missing","No issues found"))))) -> No issues found
A30: TXN-0029 | B30: USR-5506 | C30: 45311 | D30: Transfer | E30: 112860 | F30: Success | G30: App | I30: =IF(COUNTIF($A$2:$A$51,A30)>1,"DUPLICATE","OK") -> OK | J30: =IF(E30<0,"NEGATIVE","OK") -> OK | K30: =IF(YEAR(C30)<>2024,"BAD YEAR: "&YEAR(C30),"OK") -> OK | L30: =IF(AND(F30<>"Success",F30<>"Failed",F30<>"Pending"),"BAD CASING: '"&F30&"'","OK") -> OK | M30: =IF(H30="","MISSING","OK") -> MISSING | N30: =IF(I30="DUPLICATE","Duplicate ID: "&A30,IF(J30="NEGATIVE","Negative amount: ₦"&TEXT(E30,"#,##0"),IF(K30<>"OK","Date outlier: "&TEXT(C30,"DD-MMM-YYYY"),IF(L30<>"OK","Status casing: '"&F30&"' should be title case",IF(M30="MISSING","Region: NULL/missing","No issues found"))))) -> Region: NULL/missing
A31: TXN-0030 | B31: USR-5506 | C31: 45305 | D31: Deposit | E31: 4780 | F31: Success | G31: Web | H31: Abuja | I31: =IF(COUNTIF($A$2:$A$51,A31)>1,"DUPLICATE","OK") -> OK | J31: =IF(E31<0,"NEGATIVE","OK") -> OK | K31: =IF(YEAR(C31)<>2024,"BAD YEAR: "&YEAR(C31),"OK") -> OK | L31: =IF(AND(F31<>"Success",F31<>"Failed",F31<>"Pending"),"BAD CASING: '"&F31&"'","OK") -> OK | M31: =IF(H31="","MISSING","OK") -> OK | N31: =IF(I31="DUPLICATE","Duplicate ID: "&A31,IF(J31="NEGATIVE","Negative amount: ₦"&TEXT(E31,"#,##0"),IF(K31<>"OK","Date outlier: "&TEXT(C31,"DD-MMM-YYYY"),IF(L31<>"OK","Status casing: '"&F31&"' should be title case",IF(M31="MISSING","Region: NULL/missing","No issues found"))))) -> No issues found
A32: TXN-0031 | B32: USR-2424 | C32: 45304 | D32: Airtime | E32: 2960 | F32: Success | G32: App | H32: Lagos | I32: =IF(COUNTIF($A$2:$A$51,A32)>1,"DUPLICATE","OK") -> OK | J32: =IF(E32<0,"NEGATIVE","OK") -> OK | K32: =IF(YEAR(C32)<>2024,"BAD YEAR: "&YEAR(C32),"OK") -> OK | L32: =IF(AND(F32<>"Success",F32<>"Failed",F32<>"Pending"),"BAD CASING: '"&F32&"'","OK") -> OK | M32: =IF(H32="","MISSING","OK") -> OK | N32: =IF(I32="DUPLICATE","Duplicate ID: "&A32,IF(J32="NEGATIVE","Negative amount: ₦"&TEXT(E32,"#,##0"),IF(K32<>"OK","Date outlier: "&TEXT(C32,"DD-MMM-YYYY"),IF(L32<>"OK","Status casing: '"&F32&"' should be title case",IF(M32="MISSING","Region: NULL/missing","No issues found"))))) -> No issues found
A33: TXN-0032 | B33: USR-4257 | C33: 45298 | D33: Deposit | E33: 2670 | F33: Failed | G33: Web | H33: Kano | I33: =IF(COUNTIF($A$2:$A$51,A33)>1,"DUPLICATE","OK") -> OK | J33: =IF(E33<0,"NEGATIVE","OK") -> OK | K33: =IF(YEAR(C33)<>2024,"BAD YEAR: "&YEAR(C33),"OK") -> OK | L33: =IF(AND(F33<>"Success",F33<>"Failed",F33<>"Pending"),"BAD CASING: '"&F33&"'","OK") -> OK | M33: =IF(H33="","MISSING","OK") -> OK | N33: =IF(I33="DUPLICATE","Duplicate ID: "&A33,IF(J33="NEGATIVE","Negative amount: ₦"&TEXT(E33,"#,##0"),IF(K33<>"OK","Date outlier: "&TEXT(C33,"DD-MMM-YYYY"),IF(L33<>"OK","Status casing: '"&F33&"' should be title case",IF(M33="MISSING","Region: NULL/missing","No issues found"))))) -> No issues found
A34: TXN-0033 | B34: USR-3286 | C34: 45306 | D34: Deposit | E34: 473150 | F34: Success | G34: Web | H34: Lagos | I34: =IF(COUNTIF($A$2:$A$51,A34)>1,"DUPLICATE","OK") -> OK | J34: =IF(E34<0,"NEGATIVE","OK") -> OK | K34: =IF(YEAR(C34)<>2024,"BAD YEAR: "&YEAR(C34),"OK") -> OK | L34: =IF(AND(F34<>"Success",F34<>"Failed",F34<>"Pending"),"BAD CASING: '"&F34&"'","OK") -> OK | M34: =IF(H34="","MISSING","OK") -> OK | N34: =IF(I34="DUPLICATE","Duplicate ID: "&A34,IF(J34="NEGATIVE","Negative amount: ₦"&TEXT(E34,"#,##0"),IF(K34<>"OK","Date outlier: "&TEXT(C34,"DD-MMM-YYYY"),IF(L34<>"OK","Status casing: '"&F34&"' should be title case",IF(M34="MISSING","Region: NULL/missing","No issues found"))))) -> No issues found
A35: TXN-0034 | B35: USR-3547 | C35: 45296 | D35: Bill Payment | E35: -439240 | F35: Success | G35: Web | H35: Ibadan | I35: =IF(COUNTIF($A$2:$A$51,A35)>1,"DUPLICATE","OK") -> OK | J35: =IF(E35<0,"NEGATIVE","OK") -> NEGATIVE | K35: =IF(YEAR(C35)<>2024,"BAD YEAR: "&YEAR(C35),"OK") -> OK | L35: =IF(AND(F35<>"Success",F35<>"Failed",F35<>"Pending"),"BAD CASING: '"&F35&"'","OK") -> OK | M35: =IF(H35="","MISSING","OK") -> OK | N35: =IF(I35="DUPLICATE","Duplicate ID: "&A35,IF(J35="NEGATIVE","Negative amount: ₦"&TEXT(E35,"#,##0"),IF(K35<>"OK","Date outlier: "&TEXT(C35,"DD-MMM-YYYY"),IF(L35<>"OK","Status casing: '"&F35&"' should be title case",IF(M35="MISSING","Region: NULL/missing","No issues found"))))) -> Negative amount: ₦-439,240
A36: TXN-0035 | B36: USR-2679 | C36: 45314 | D36: Bill Payment | E36: 46560 | F36: Success | G36: Web | H36: Lagos | I36: =IF(COUNTIF($A$2:$A$51,A36)>1,"DUPLICATE","OK") -> OK | J36: =IF(E36<0,"NEGATIVE","OK") -> OK | K36: =IF(YEAR(C36)<>2024,"BAD YEAR: "&YEAR(C36),"OK") -> OK | L36: =IF(AND(F36<>"Success",F36<>"Failed",F36<>"Pending"),"BAD CASING: '"&F36&"'","OK") -> OK | M36: =IF(H36="","MISSING","OK") -> OK | N36: =IF(I36="DUPLICATE","Duplicate ID: "&A36,IF(J36="NEGATIVE","Negative amount: ₦"&TEXT(E36,"#,##0"),IF(K36<>"OK","Date outlier: "&TEXT(C36,"DD-MMM-YYYY"),IF(L36<>"OK","Status casing: '"&F36&"' should be title case",IF(M36="MISSING","Region: NULL/missing","No issues found"))))) -> No issues found
A37: TXN-0036 | B37: USR-5506 | C37: 45312 | D37: Withdrawal | E37: 7890 | F37: Failed | G37: Web | H37: Abuja | I37: =IF(COUNTIF($A$2:$A$51,A37)>1,"DUPLICATE","OK") -> OK | J37: =IF(E37<0,"NEGATIVE","OK") -> OK | K37: =IF(YEAR(C37)<>2024,"BAD YEAR: "&YEAR(C37),"OK") -> OK | L37: =IF(AND(F37<>"Success",F37<>"Failed",F37<>"Pending"),"BAD CASING: '"&F37&"'","OK") -> OK | M37: =IF(H37="","MISSING","OK") -> OK | N37: =IF(I37="DUPLICATE","Duplicate ID: "&A37,IF(J37="NEGATIVE","Negative amount: ₦"&TEXT(E37,"#,##0"),IF(K37<>"OK","Date outlier: "&TEXT(C37,"DD-MMM-YYYY"),IF(L37<>"OK","Status casing: '"&F37&"' should be title case",IF(M37="MISSING","Region: NULL/missing","No issues found"))))) -> No issues found
A38: TXN-0037 | B38: USR-1106 | C38: 45306 | D38: Deposit | E38: 4000 | F38: Success | G38: USSD | I38: =IF(COUNTIF($A$2:$A$51,A38)>1,"DUPLICATE","OK") -> OK | J38: =IF(E38<0,"NEGATIVE","OK") -> OK | K38: =IF(YEAR(C38)<>2024,"BAD YEAR: "&YEAR(C38),"OK") -> OK | L38: =IF(AND(F38<>"Success",F38<>"Failed",F38<>"Pending"),"BAD CASING: '"&F38&"'","OK") -> OK | M38: =IF(H38="","MISSING","OK") -> MISSING | N38: =IF(I38="DUPLICATE","Duplicate ID: "&A38,IF(J38="NEGATIVE","Negative amount: ₦"&TEXT(E38,"#,##0"),IF(K38<>"OK","Date outlier: "&TEXT(C38,"DD-MMM-YYYY"),IF(L38<>"OK","Status casing: '"&F38&"' should be title case",IF(M38="MISSING","Region: NULL/missing","No issues found"))))) -> Region: NULL/missing
A39: TXN-0038 | B39: USR-1409 | C39: 45318 | D39: Bill Payment | E39: 1710 | F39: Success | G39: App | H39: Kano | I39: =IF(COUNTIF($A$2:$A$51,A39)>1,"DUPLICATE","OK") -> OK | J39: =IF(E39<0,"NEGATIVE","OK") -> OK | K39: =IF(YEAR(C39)<>2024,"BAD YEAR: "&YEAR(C39),"OK") -> OK | L39: =IF(AND(F39<>"Success",F39<>"Failed",F39<>"Pending"),"BAD CASING: '"&F39&"'","OK") -> OK | M39: =IF(H39="","MISSING","OK") -> OK | N39: =IF(I39="DUPLICATE","Duplicate ID: "&A39,IF(J39="NEGATIVE","Negative amount: ₦"&TEXT(E39,"#,##0"),IF(K39<>"OK","Date outlier: "&TEXT(C39,"DD-MMM-YYYY"),IF(L39<>"OK","Status casing: '"&F39&"' should be title case",IF(M39="MISSING","Region: NULL/missing","No issues found"))))) -> No issues found
A40: TXN-0039 | B40: USR-2679 | C40: 45313 | D40: Airtime | E40: 459000 | F40: PENDING | G40: Agent | H40: Ibadan | I40: =IF(COUNTIF($A$2:$A$51,A40)>1,"DUPLICATE","OK") -> OK | J40: =IF(E40<0,"NEGATIVE","OK") -> OK | K40: =IF(YEAR(C40)<>2024,"BAD YEAR: "&YEAR(C40),"OK") -> OK | L40: =IF(AND(F40<>"Success",F40<>"Failed",F40<>"Pending"),"BAD CASING: '"&F40&"'","OK") -> OK | M40: =IF(H40="","MISSING","OK") -> OK | N40: =IF(I40="DUPLICATE","Duplicate ID: "&A40,IF(J40="NEGATIVE","Negative amount: ₦"&TEXT(E40,"#,##0"),IF(K40<>"OK","Date outlier: "&TEXT(C40,"DD-MMM-YYYY"),IF(L40<>"OK","Status casing: '"&F40&"' should be title case",IF(M40="MISSING","Region: NULL/missing","No issues found"))))) -> No issues found
...

Sheet data_profile
A1: DATA PROFILE: palmpay_transactions_jan2024 | January 2024
A2: Column Name | B2: Data Type | C2: Total Values | D2: Blank / Null Count | E2: Unique Value Count | F2: Min Value | G2: Max Value | H2: Average / Notes | I2: Issues Found?
A3: transaction_id | B3: Text / String | C3: =COUNTA(transactions_jan2024!A2:A51) -> 50 | D3: =COUNTBLANK(transactions_jan2024!A2:A51) -> 0 | E3: =SUMPRODUCT(1/COUNTIF(transactions_jan2024!A2:A51,transactions_jan2024!A2:A51)) -> 48 | F3: TXN-0001 | G3: TXN-0050 | H3: Sequential IDs. 2 IDs appear twice: TXN-0003 (rows 3 & 8) and TXN-0015 (rows 15 & 22). | I3: YES. 2 DUPLICATE IDs
A4: user_id | B4: Text / String | C4: =COUNTA(transactions_jan2024!B2:B51) -> 50 | D4: =COUNTBLANK(transactions_jan2024!B2:B51) -> 0 | E4: =SUMPRODUCT(1/COUNTIF(transactions_jan2024!B2:B51,transactions_jan2024!B2:B51)) -> 22 | F4: N/A | G4: N/A | H4: Customer IDs. Multiple transactions per user is expected behaviour. | I4: NO
A5: transaction_date | B5: Date | C5: =COUNTA(transactions_jan2024!C2:C51) -> 50 | D5: =COUNTBLANK(transactions_jan2024!C2:C51) -> 0 | E5: =SUMPRODUCT(1/COUNTIF(transactions_jan2024!C2:C51,transactions_jan2024!C2:C51)) -> 26 | F5: =TEXT(MIN(transactions_jan2024!C2:C51),"DD-MMM-YYYY") -> 17-Jan-2004 | G5: =TEXT(MAX(transactions_jan2024!C2:C51),"DD-MMM-YYYY") -> 31-Jan-2024 | H5: Covers Jan 2024 EXCEPT row 17 which shows 17-Jan-2004. | I5: YES. 1 DATE OUTLIER (row 17, year 2004)
A6: transaction_type | B6: Text / String | C6: =COUNTA(transactions_jan2024!D2:D51) -> 50 | D6: =COUNTBLANK(transactions_jan2024!D2:D51) -> 0 | E6: =SUMPRODUCT(1/COUNTIF(transactions_jan2024!D2:D51,transactions_jan2024!D2:D51)) -> 5 | F6: Airtime | G6: Withdrawal | H6: 5 types: Transfer, Airtime, Bill Payment, Withdrawal, Deposit. All correctly cased. | I6: NO
A7: amount_ngn | B7: Number (₦) | C7: =COUNTA(transactions_jan2024!E2:E51) -> 50 | D7: =COUNTBLANK(transactions_jan2024!E2:E51) -> 0 | E7: =SUMPRODUCT(1/COUNTIF(transactions_jan2024!E2:E51,transactions_jan2024!E2:E51)) -> 50 | F7: =MIN(transactions_jan2024!E2:E51) -> -439240 | G7: =MAX(transactions_jan2024!E2:E51) -> 473150 | H7: Range ₦500–₦500,000 EXCEPT rows 10 & 34 which are negative. MIN reflects this. | I7: YES. 2 NEGATIVE AMOUNTS (rows 10 & 34)
A8: status | B8: Text / String | C8: =COUNTA(transactions_jan2024!F2:F51) -> 50 | D8: =COUNTBLANK(transactions_jan2024!F2:F51) -> 0 | E8: =SUMPRODUCT(1/COUNTIF(transactions_jan2024!F2:F51,transactions_jan2024!F2:F51)) -> 3 | F8: N/A | G8: N/A | H8: Should be 3 values: Success, Failed, Pending. Found 8 due to casing errors: 'success', 'SUCCESS', 'failed', 'PENDING'. Rows affected: 6, 13, 25, 39, 44. | I8: YES. 5 CASING ERRORS (rows 6,13,25,39,44)
A9: channel | B9: Text / String | C9: =COUNTA(transactions_jan2024!G2:G51) -> 50 | D9: =COUNTBLANK(transactions_jan2024!G2:G51) -> 0 | E9: =SUMPRODUCT(1/COUNTIF(transactions_jan2024!G2:G51,transactions_jan2024!G2:G51)) -> 4 | F9: Agent | G9: USSD | H9: 4 channels: App, USSD, Web, Agent. All consistent and correctly cased. | I9: NO
A10: region | B10: Text / String | C10: =COUNTA(transactions_jan2024!H2:H51) -> 45 | D10: =COUNTBLANK(transactions_jan2024!H2:H51) -> 5 | E10: =SUMPRODUCT((transactions_jan2024!H2:H51<>"")/COUNTIF(transactions_jan2024!H2:H51,transactions_jan2024!H2:H51&"")) -> 5 | F10: Abuja | G10: Port Harcourt | H10: 5 of 50 rows have NULL region: Rows 5, 12, 20, 29, 37. Cannot assign to regional analysis. | I10: YES. 5 MISSING VALUES (rows 5,12,20,29,37)

Sheet analyst_summary
A1: PalmPay Analytics — January 2024 Dataset Review
A2: Analyst: Junior Data Analyst | Date: January 2024 | Status: Draft
A3: SECTION 1 — DATASET OVERVIEW
A4: Dataset Name | B4: palmpay_transactions_jan2024.xlsx
A5: Time Period Covered | B5: January 1–31, 2024. NOTE: One row contains 17-Jan-2004 which is a data entry error — it should be 2024.
A6: Total Records (rows) | B6: 50 transaction records (rows 2–51 in Excel, excluding the header row)
A7: Total Columns | B7: 8 columns: transaction_id, user_id, transaction_date, transaction_type, amount_ngn, status, channel, region
A8: What does ONE row represent? | B8: One individual financial transaction made by one customer on one date via one channel. Example: A transfer of ₦29,900 by USR-3615 on 1-Jan-2024 via Web in Lagos. This is the grain of the data — understanding this prevents miscounting.
A9: Key dimensions available | B9: WHO: user_id (customer identity) WHAT: transaction_type (Transfer/Airtime/Bill Payment/Withdrawal/Deposit), amount_ngn (value in ₦) WHEN: transaction_date (Jan 2024) HOW: channel (App / USSD / Web / Agent) WHERE: region (Lagos / Abuja / Kano / Port Harcourt / Ibadan) OUTCOME: status (Success / Failed / Pending)
A11: SECTION 2 — DATA QUALITY ISSUES FOUND
A12: Issue 1 — Duplicate Transaction IDs | B12: 2 duplicate IDs found: • TXN-0003 appears in rows 3 AND 8 (two completely different transactions with the same ID) • TXN-0015 appears in rows 15 AND 22 Business Risk: If we SUM revenue or COUNT transactions, these will be double-counted. Could inflate total transaction volume by over ₦700,000.
A13: Issue 2 — Missing Region Values | B13: 5 rows have NULL/blank region: rows 5, 12, 20, 29, and 37. Business Risk: Any regional performance report (e.g. Lagos vs Kano) will silently exclude these 5 transactions. Regional totals will be wrong without any error message.
A14: Issue 3 — Negative Transaction Amounts | B14: 2 rows have negative amounts: • Row 10: ₦-250,080 (USR-7924, Withdrawal via Web) • Row 34: ₦-439,240 (USR-3547, Bill Payment via Web) Business Risk: A SUM of all amounts gives incorrect total volume. These may be reversals, refunds, or system errors — must be confirmed before any calculation.
A15: Issue 4 — Inconsistent Status Casing | B15: The status column should only contain: Success, Failed, Pending (title case). Found 5 rows using wrong casing: 'success' (rows 6, 44), 'SUCCESS' (row 13), 'failed' (row 25), 'PENDING' (row 39). Business Risk: =COUNTIF(F:F,"Success") will UNDERCOUNT successes — missing all lowercase/uppercase variants. Every KPI based on this column (success rate, failure rate) will be inaccurate.
A16: Issue 5 — Date Outlier | B16: Row 17 contains a transaction date of 17-Jan-2004 — exactly 20 years before the rest of the dataset. Business Risk: MIN(date) returns 2004. Daily trend charts will have a phantom data point 20 years back. Time-series analysis will appear broken.
A17: Overall Data Readiness | B17: ⚠ NOT READY FOR ANALYSIS. Must fix before drawing conclusions: 1. Standardise status casing — use PROPER() or UPPER() function 2. Investigate the 2 negative amounts — confirm if reversals or errors 3. Correct or exclude the 2004 date outlier in row 17 4. Resolve the 2 duplicate transaction IDs — determine which record is correct 5. Recover the 5 missing region values from source systems if possible Data can be used for rough directional analysis ONLY with all caveats documented.
A19: SECTION 3 — THREE BUSINESS QUESTIONS THIS DATA CAN ANSWER
A20: Business Question 1 | B20: Which transaction channel (App, USSD, Web, Agent) had the highest failure rate in January 2024?
A21: Why it matters | B21: If USSD has a 40% failure rate vs App's 10%, the product and engineering teams know exactly where to invest. Customers on failing channels churn. This directly impacts Monthly Active Users (MAU).
A22: Business Question 2 | B22: Which region generated the highest total transaction volume (₦) — and which region had the most failed transactions in January 2024?
A23: Why it matters | B23: High volume + high failure rate in the same region signals an infrastructure or network reliability problem. This guides where operations and engineering should focus to protect revenue.
A24: Business Question 3 | B24: What is the success rate per transaction type — and which type accounts for the largest share of total transaction value?
A25: Why it matters | B25: If Bill Payments fail 30% of the time but represent 50% of total revenue processed, that is the single highest-priority product fix. Combines reliability analysis with revenue impact — the language of executives.

Sheet quick_stats
A1: ⚡ BONUS QUICK STATS — Excel Formula Answers
A2: Question | B2: Excel Formula | C2: Answer | D2: Explanation
A3: Total transaction volume (₦ sum of all amounts) | B3: =SUM(transactions_jan2024!E2:E51) -> 6145400 | C3: =SUM(transactions_jan2024!E2:E51) -> 6145400 | D3: SUM adds every value including the 2 negatives. Clean data first for true gross volume.
A4: % of transactions that were Successful | B4: =COUNTIF(transactions_jan2024!F2:F51,"Success")/COUNTA(transactions_jan2024!F2:F51) -> 0.72 | C4: =COUNTIF(transactions_jan2024!F2:F51,"Success")/COUNTA(transactions_jan2024!F2:F51) -> 0.72 | D4: ⚠ Undercounts! Casing errors mean 'success'/'SUCCESS' are missed. Clean status first.
A5: Most frequent transaction type | B5: Use COUNTIF for each type separately | C5: Airtime (12 transactions) | D5: No single formula gives text mode. Use COUNTIF per type: =COUNTIF(D2:D51,"Airtime") etc.
A6: Average transaction amount — Withdrawals only | B6: =AVERAGEIF(transactions_jan2024!D2:D51,"Withdrawal",transactions_jan2024!E2:E51) -> 71465.455 | C6: =AVERAGEIF(transactions_jan2024!D2:D51,"Withdrawal",transactions_jan2024!E2:E51) -> 71465.455 | D6: AVERAGEIF filters rows where type=Withdrawal before averaging. Correct approach.
A7: Count of unique users | B7: =SUMPRODUCT(1/COUNTIF(transactions_jan2024!B2:B51,transactions_jan2024!B2:B51)) -> 22 | C7: =SUMPRODUCT(1/COUNTIF(transactions_jan2024!B2:B51,transactions_jan2024!B2:B51)) -> 22 | D7: SUMPRODUCT(1/COUNTIF) divides 1 by frequency of each value then sums — elegant unique count trick.
A8: Channel with most failed transactions | B8: =COUNTIFS(transactions_jan2024!G2:G51,"Web",transactions_jan2024!F2:F51,"Failed") -> 5 | C8: Web — 5 failed transactions | D8: Use COUNTIFS with two criteria: channel AND status=Failed. Run for all 4 channels and compare.
A9: Largest single transaction & which user made it | B9: Step 1: =MAX(transactions_jan2024!E2:E51) Step 2: =INDEX(B2:B51,MATCH(MAX(E2:E51),E2:E51,0)) | C9: ₦473,150 by USR-3286 | D9: INDEX/MATCH is the professional alternative to VLOOKUP — finds a value and returns a related field.
